[{"source": "base_8500", "category": "Error", "name": "unhandled_error", "message": "unexpected exception in run 'pydss_simulation' job=base_8500 - 2 errors occurred", "event_class": "StructuredErrorLogEvent", "timestamp": "2024-01-18 00:06:23.986897", "data": {"error": "2 errors occurred", "exception": "<class 'PyDSS.exceptions.OpenDssConvergenceErrorCountExceeded'>", "filename": "run.py", "lineno": 73}}]